<mujoco model="p73_walker">
  <compiler angle="radian" meshdir="../meshes/"/>

  <default>
    <default class="waist_yaw_motor">
      <joint damping="2.5" armature="0.16" frictionloss="5.0"/>
    </default>
    <default class="hip_roll_motor">
      <joint damping="2.5" armature="0.96" frictionloss="5.0"/>
    </default>
    <default class="hip_pitch_motor">
      <joint damping="2.5" armature="0.375" frictionloss="5.0"/>
    </default>
    <default class="hip_yaw_motor">
      <joint damping="1.0" armature="0.0625" frictionloss="2.0"/>
    </default>
    <default class="knee_pitch_motor">
      <joint damping="2.0" armature="0.375" frictionloss="3.0"/>
    </default>
    <default class="ankle_roll_motor">
      <joint damping="1.0" armature="0.0625" frictionloss="2.0"/>
    </default>
    <default class="ankle_pitch_motor">
      <joint damping="1.0" armature="0.0625" frictionloss="2.0"/>
    </default>
    <default class="viz">
      <geom contype="0" conaffinity="0" group="1" type="mesh" rgba="1.0 1.0 1.0 1" />
    </default>
    <default class="cls">
      <geom group="2" rgba="0 0 1 0.3"/>
      <default class="cls_torso">
        <geom contype="2" conaffinity="255"/>
      </default>
      <default class="cls_lleg">
        <geom contype="16" conaffinity="255"/>
      </default>
      <default class="cls_rleg">
        <geom contype="32" conaffinity="255"/>
      </default>
    </default>
  </default>

  <asset>
    <mesh name="base_link" file="base_link.stl" scale="0.001 0.001 0.001"/>
    <mesh name="WaistYaw_Link" file="WaistYaw_Link.stl" scale="0.001 0.001 0.001"/>
    <mesh name="R_HipRoll_Link" file="R_HipRoll_Link.stl" scale="0.001 0.001 0.001"/>
    <mesh name="L_HipRoll_Link" file="L_HipRoll_Link.stl" scale="0.001 0.001 0.001"/>
    <mesh name="R_HipPitch_Link" file="R_HipPitch_Link.stl" scale="0.001 0.001 0.001"/>
    <mesh name="L_HipPitch_Link" file="L_HipPitch_Link.stl" scale="0.001 0.001 0.001"/>
    <mesh name="R_Thigh_Link" file="R_Thigh_Link.stl" scale="0.001 0.001 0.001"/>
    <mesh name="L_Thigh_Link" file="L_Thigh_Link.stl" scale="0.001 0.001 0.001"/>
    <mesh name="R_Knee_Link" file="R_Knee_Link.stl" scale="0.001 0.001 0.001"/>
    <mesh name="L_Knee_Link" file="L_Knee_Link.stl" scale="0.001 0.001 0.001"/>
    <mesh name="L_AnkleRoll_Link" file="L_AnkleRoll_Link.stl" scale="0.001 0.001 0.001"/>
    <mesh name="R_AnkleRoll_Link" file="R_AnkleRoll_Link.stl" scale="0.001 0.001 0.001"/>
    <mesh name="L_Foot_Link" file="L_Foot_Link.stl" scale="0.001 0.001 0.001"/>
    <mesh name="R_Foot_Link" file="R_Foot_Link.stl" scale="0.001 0.001 0.001"/>

    <texture type="skybox" builtin="gradient" width="128" height="128" rgb1="0.4 0.6 0.8" rgb2="0 0 0"/>
    <texture name="texplane" type="2d" builtin="checker" rgb1=".4 .4 .4" rgb2=".6 .6 .6" width="512" height="512"/>
    <material name='MatPlane' reflectance='0.3' texture="texplane" texrepeat="1 1" texuniform="true"/>
    <material name="silver" rgba="0.8 0.8 0.8 1.0"/>
    <material name="blue" rgba="0.0 0.0 1.0 1.0"/>
  </asset>

  <worldbody>
    <geom name="ground" type="plane" pos="0 0 0" size="10 10 1.0" rgba="0.7 0.6 0.5 1" material="MatPlane" group="3"/>
    <light directional="true" diffuse=".8 .8 .8" pos="0 0 10" dir="0 0 -10"/>
    <light directional="true" diffuse=".5 .5 .5" pos="10 0 0" dir="-10 0 0"/>

    <body name="base_link">
      <inertial pos="0.00118423 8.43237e-05 0.0218623" quat="0.520509 0.476955 0.480298 0.520479" mass="5.47506" diaginertia="0.0323962 0.0262879 0.0208649"/>
      <joint name="world_to_base" type="free" limited="false" actuatorfrclimited="false" />
      <geom type="mesh" contype="0" conaffinity="0" density="0" mesh="base_link" material="blue" group="1"/>
      <!-- Collision: pelvis/torso -->
      <geom class="cls_torso" name="L_Pelvis" size="0.07 0.02" pos="0 0.0 0" type="capsule"/>

      <body name="L_HipRoll_Link" pos="-0.0155 0 0">
        <inertial pos="0.0124197 0.0490939 -0.000127375" quat="0.713726 0.69689 -0.0416249 -0.0566259" mass="1.27027" diaginertia="0.00206605 0.00180727 0.00123469"/>
        <joint name="L_HipRoll_Joint" class="hip_roll_motor" pos="0 0 0" axis="1 0 0" range="-0.58 0.3" actuatorfrcrange="-352 352"/>
        <geom pos="0.0155 0 0" quat="1 0 0 0" type="mesh" contype="0" conaffinity="0" group="1" density="0" mesh="L_HipRoll_Link" material="silver"/>
        <geom pos="0.0155 0 0" quat="1 0 0 0" type="mesh" contype="0" conaffinity="0" mesh="L_HipRoll_Link" rgba="0.8 0.8 0.8 1"/>
        <body name="L_HipPitch_Link" pos="0.0155 0.0805 0">
          <inertial pos="0.00471255 0.0463623 -0.0672883" quat="0.699545 -0.0352894 0.0214462 0.713394" mass="6.85744" diaginertia="0.064219 0.0569434 0.0279425"/>
          <joint name="L_HipPitch_Joint" class="hip_pitch_motor" pos="0 0 0" axis="0 1 0" range="-2.09 1.57" actuatorfrcrange="-220 220"/>
          <geom pos="0 -0.0805 0" quat="1 0 0 0" type="mesh" contype="0" conaffinity="0" group="1" density="0" mesh="L_HipPitch_Link" material="silver"/>
            <geom class="cls_lleg" name="L_Upper_Leg1" size="0.075 0.085" quat="0.9981 0 -0.0610 0"  pos="0.04 0.05 -0.08" type="capsule"/>
            <geom class="cls_lleg" name="L_Upper_Leg2" size="0.07 0.089" pos="-0.02 0.06 -0.08" type="capsule"/>
          <!-- <geom class="cls" size="0.1 0.055 0.13" pos="0.015 0.0625 -0.06" type="box" />
          <geom class="cls" size="0.1 0.015 0.045" pos="0.015 -0.0075 -0.145" type="box" /> -->
          <body name="L_Thigh_Link" pos="0 0.04 -0.202">
            <inertial pos="0.00687715 -0.00249606 -0.0919431" quat="0.693505 0.0874998 0.0786175 0.710784" mass="4.90328" diaginertia="0.040768 0.0370279 0.0240011"/>
            <joint name="L_HipYaw_Joint" class="hip_yaw_motor" pos="0 0 0" axis="0 0 -1" range="-0.78 0.78" actuatorfrcrange="-220 220"/>
            <geom pos="0 -0.1205 0.202" quat="1 0 0 0" type="mesh" contype="0" conaffinity="0" group="1" density="0" mesh="L_Thigh_Link" material="silver"/>
            <!-- Collision: left upper leg -->
              <geom class="cls_lleg" name="L_Lower_Leg1" size="0.09 0.06" pos="-0.0 0.01 -0.095" type="capsule"/>
              <geom class="cls_lleg" name="L_Lower_Leg2" size="0.08 0.06" quat="0.9990 0 0.0436 0" pos="0.055 0.0 -0.115" type="capsule"/>
          
            <body name="L_Knee_Link" pos="-0.042753 -0.0195 -0.198462">
              <inertial pos="0.0564446 0.0181463 -0.166162" quat="0.699176 0.00776861 0.0179462 0.714682" mass="8.18145" diaginertia="0.134494 0.131901 0.0170098"/>
              <joint name="L_Knee_Joint" class="knee_pitch_motor" pos="0 0 0" axis="0 -1 0" range="-2.56 0" actuatorfrcrange="-95 95"/>
              <geom pos="0.042753 -0.101 0.400462" quat="1 0 0 0" type="mesh" contype="0" conaffinity="0" group="1" density="0" mesh="L_Knee_Link" material="silver"/>
              <!-- Collision: left lower leg -->
              <geom class="cls_lleg" name="L_Lower_Leg3" size="0.068 0.15" pos="0.055 0.02 -0.2" type="capsule"/>
              
              <body name="L_AnkleRoll_Link" pos="0.043642 -0.0025 -0.415855">
                <inertial pos="-0.000538633 0.0234999 -0.00113648" quat="0.5 0.5 -0.5 0.5" mass="0.161268" diaginertia="6.8e-05 5.4e-05 3.2e-05"/>
                <joint name="L_AnklePitch_Joint" class="ankle_pitch_motor" pos="0 0 0" axis="0 -1 0" range="-0.7 1.05" actuatorfrcrange="-95 95"/>
                <geom pos="-0.000889 -0.0985 0.816317" quat="1 0 0 0" type="mesh" contype="0" conaffinity="0" group="1" density="0" mesh="L_AnkleRoll_Link" material="silver"/>
                <geom pos="-0.000889 -0.0985 0.816317" quat="1 0 0 0" type="mesh" contype="0" conaffinity="0" mesh="L_AnkleRoll_Link" rgba="0.8 0.8 0.8 1"/>
                <body name="L_Foot_Link" pos="0.011 0.0235 0">
                  <inertial pos="0.0390789 8.77121e-09 -0.0626394" quat="0 0.722655 0 0.691209" mass="2.32904" diaginertia="0.0143825 0.012898 0.00251755"/>
                  <joint name="L_AnkleRoll_Joint" class="ankle_roll_motor" pos="0 0 0" axis="1 0 0" range="-0.42 0.42" actuatorfrcrange="-95 95"/>
                  <geom pos="-0.011889 -0.122 0.816317" quat="1 0 0 0" type="mesh" contype="0" conaffinity="0" group="1" density="0" mesh="L_Foot_Link" material="blue"/>
                  <!-- Collision: left foot -->
                  <geom class="cls_lleg" name="L_Foot" size="0.05 0.11" pos="0.06 0 -0.05" quat="0.707107 0 -0.707107 0" type="capsule"/>
                </body>
              </body>
            </body>
          </body>
        </body>
      </body>

      <body name="R_HipRoll_Link" pos="0.0155 0 0">
        <inertial pos="-0.0138626 -0.045575 -0.000138455" quat="0.695083 0.713545 -0.0610603 -0.0631207" mass="1.17879" diaginertia="0.00200213 0.00174939 0.00114848"/>
        <joint name="R_HipRoll_Joint" class="hip_roll_motor" pos="0 0 0" axis="1 0 0" range="-0.3 0.58" actuatorfrcrange="-352 352"/>
        <geom pos="-0.0155 0 0" quat="1 0 0 0" type="mesh" contype="0" conaffinity="0" group="1" density="0" mesh="R_HipRoll_Link" material="silver"/>
        <!-- <geom class="cls" size="0.1 0.055 0.13" pos="0.015 -0.0625 -0.06" type="box" /> -->
        <body name="R_HipPitch_Link" pos="-0.0155 -0.0805 0">
          <inertial pos="0.00471264 -0.0463621 -0.067288" quat="0.ss13394 0.0214462 -0.0352894 0.699545" mass="6.85746" diaginertia="0.064219 0.0569434 0.0279425"/>
          <joint name="R_HipPitch_Joint" class="hip_pitch_motor" pos="0 0 0" axis="0 -1 0" range="-1.57 2.09" actuatorfrcrange="-220 220"/>
          <geom pos="0 0.0805 0" quat="1 0 0 0" type="mesh" contype="0" conaffinity="0" group="1" density="0" mesh="R_HipPitch_Link" material="silver"/>
            <geom class="cls_lleg" name="R_Upper_Leg1" size="0.075 0.085" quat="0.9981 0 -0.0610 0"  pos="0.04 -0.05 -0.08" type="capsule"/>
            <geom class="cls_lleg" name="R_Upper_Leg2" size="0.07 0.089" pos="-0.02 -0.06 -0.08" type="capsule"/>
          
          <body name="R_Thigh_Link" pos="0 -0.04 -0.202">
            <inertial pos="0.00671945 0.00318273 -0.0917388" quat="0.714512 0.0771894 0.0882891 0.689724" mass="4.99569" diaginertia="0.0408711 0.037235 0.024211"/>
            <joint name="R_HipYaw_Joint" class="hip_yaw_motor" pos="0 0 0" axis="0 0 -1" range="-0.78 0.78" actuatorfrcrange="-220 220"/>
            <geom pos="0 0.1205 0.202" quat="1 0 0 0" type="mesh" contype="0" conaffinity="0" group="1" density="0" mesh="R_Thigh_Link" material="silver"/>
            <!-- Collision: right upper leg -->
              <geom class="cls_rleg" name="R_Lower_Leg1" size="0.09 0.06" pos="-0.0 -0.01 -0.095" type="capsule"/>
              <geom class="cls_rleg" name="R_Lower_Leg2" size="0.08 0.06" quat="0.9990 0 0.0436 0" pos="0.055 0.0 -0.115" type="capsule"/>
          
            <body name="R_Knee_Link" pos="-0.042753 0.0195 -0.198462">
              <inertial pos="0.0571771 -0.0182457 -0.166829" quat="0.718312 0.0198614 0.0102388 0.695362" mass="7.96682" diaginertia="0.130318 0.1281 0.016583"/>
              <joint name="R_Knee_Joint" class="knee_pitch_motor" pos="0 0 0" axis="0 -1 0" range="-2.56 0" actuatorfrcrange="-95 95"/>
              <geom pos="0.042753 0.101 0.400462" quat="1 0 0 0" type="mesh" contype="0" conaffinity="0" group="1" density="0" mesh="R_Knee_Link" material="silver"/>
              <!-- Collision: right lower leg -->
                <geom class="cls_rleg" name="R_Lower_Leg3" size="0.068 0.15" pos="0.055 -0.02 -0.2" type="capsule"/>
              <body name="R_AnkleRoll_Link" pos="0.043642 0.0025 -0.415855">
                <inertial pos="-0.000538632 -0.0235001 -0.00113648" quat="0.5 0.5 -0.5 0.5" mass="0.161268" diaginertia="6.8e-05 5.4e-05 3.2e-05"/>
                <joint name="R_AnklePitch_Joint" class="ankle_pitch_motor" pos="0 0 0" axis="0 1 0" range="-1.05 0.7" actuatorfrcrange="-95 95"/>
                <geom pos="-0.000889 0.0985 0.816317" quat="1 0 0 0" type="mesh" contype="0" conaffinity="0" group="1" density="0" mesh="R_AnkleRoll_Link" material="silver"/>
                <geom pos="-0.000889 0.0985 0.816317" quat="1 0 0 0" type="mesh" contype="0" conaffinity="0" mesh="R_AnkleRoll_Link" rgba="0.8 0.8 0.8 1"/>
                <body name="R_Foot_Link" pos="0.011 -0.0235 0">
                  <inertial pos="0.0390789 7.20535e-09 -0.0626394" quat="0 0.722655 0 0.691209" mass="2.32904" diaginertia="0.0143825 0.012898 0.00251755"/>
                  <joint name="R_AnkleRoll_Joint" class="ankle_roll_motor" pos="0 0 0" axis="1 0 0" range="-0.42 0.42" actuatorfrcrange="-95 95"/>
                  <geom pos="-0.011889 0.122 0.816317" quat="1 0 0 0" type="mesh" contype="0" conaffinity="0" group="1" density="0" mesh="R_Foot_Link" material="blue"/>
                  <!-- Collision: right foot -->
                  <geom class="cls_rleg" name="R_Foot" size="0.05 0.11" pos="0.06 0 -0.05" quat="0.707107 0 -0.707107 0" type="capsule"/>
                </body>
              </body>
            </body>
          </body>
        </body>
      </body>

      <body name="WaistYaw_Link" pos="0 0 0.0955">
        <inertial pos="-0.00225139 0.000202761 0.243933" quat="0.999949 -0.000255431 -0.00677998 -0.00747803" mass="7.60539" diaginertia="0.205795 0.194814 0.0547032"/>
        <joint name="WaistYaw_Joint" pos="0 0 0" axis="0 0 1" range="-1.57 1.57" actuatorfrcrange="-152 152"/>
        <geom pos="0 0 -0.0955" quat="1 0 0 0" type="mesh" contype="0" conaffinity="0" group="1" density="0" mesh="WaistYaw_Link" material="silver"/>
        <!-- Collision: waist/chest -->
        <geom class="cls_torso" name="Waist" size="0.08 0.04" pos="0 0 0.05" type="capsule"/>
        <geom class="cls_torso" name="Torso" size="0.2 0.06" pos="0.0 0.0 0.28" type="capsule"/>
      </body>

  </body>

  </worldbody>

  <actuator>
    <motor name="WaistYaw_motor"     joint="WaistYaw_Joint"     gear="80" ctrllimited="true" ctrlrange="-152 152"/>

    <motor name="R_HipRoll_motor"    joint="R_HipRoll_Joint"    gear="80" ctrllimited="true" ctrlrange="-352 352"/>
    <motor name="R_HipPitch_motor"   joint="R_HipPitch_Joint"   gear="50" ctrllimited="true" ctrlrange="-220 220"/>
    <motor name="R_HipYaw_motor"     joint="R_HipYaw_Joint"     gear="50" ctrllimited="true" ctrlrange="-220 220"/>
    <motor name="R_Knee_motor"       joint="R_Knee_Joint"       gear="50" ctrllimited="true" ctrlrange="-95 95"/>
    <motor name="R_AnklePitch_motor" joint="R_AnklePitch_Joint" gear="50" ctrllimited="true" ctrlrange="-95 95"/>
    <motor name="R_AnkleRoll_motor"  joint="R_AnkleRoll_Joint"  gear="50" ctrllimited="true" ctrlrange="-95 95"/>
    <motor name="L_HipRoll_motor"    joint="L_HipRoll_Joint"    gear="80" ctrllimited="true" ctrlrange="-352 352"/>
    <motor name="L_HipPitch_motor"   joint="L_HipPitch_Joint"   gear="50" ctrllimited="true" ctrlrange="-220 220"/>
    <motor name="L_HipYaw_motor"     joint="L_HipYaw_Joint"     gear="50" ctrllimited="true" ctrlrange="-220 220"/>
    <motor name="L_Knee_motor"       joint="L_Knee_Joint"       gear="50" ctrllimited="true" ctrlrange="-95 95"/>
    <motor name="L_AnklePitch_motor" joint="L_AnklePitch_Joint" gear="50" ctrllimited="true" ctrlrange="-95 95"/>
    <motor name="L_AnkleRoll_motor"  joint="L_AnkleRoll_Joint"  gear="50" ctrllimited="true" ctrlrange="-95 95"/>
  </actuator>

<keyframe>
  <key name="stand"
       qpos="0 0 0.89  1 0 0 0   
             0   
             0 0 0 0 0 0   
             0 0 0 0 0 0"
  />
</keyframe>

</mujoco>